<?xml version="1.0" encoding="utf-8"?>
<!-- This URDF was automatically created by SolidWorks to URDF Exporter! Originally created by
Stephen Brawner (brawner@gmail.com) 
     Commit Version: 1.6.0-4-g7f85cfe  Build Version: 1.6.7995.38578
     For more information, please see http://wiki.ros.org/sw_urdf_exporter -->
<robot
  name="eva_description">
	<link
    name="model_0">
		<inertial>
			<origin
        xyz="-5.4406E-06 -0.00066159 0.070251"
        rpy="0 0 0" />
			<mass
        value="2.1444" />
			<inertia
        ixx="0.0067679"
        ixy="-1.3981E-07"
        ixz="-2.7068E-09"
        iyy="0.006721"
        iyz="-1.5676E-06"
        izz="0.0049876" />
		</inertial>
		<visual>
			<origin
        xyz="0 0 0"
        rpy="0 0 0" />
			<geometry>
				<mesh filename="../meshes/model_0.dae" />
			</geometry>
		</visual>
		<collision>
			<origin
        xyz="0 0 0"
        rpy="0 0 0" />
			<geometry>
				<mesh filename="../collision_meshes/model_0.STL" />
			</geometry>
		</collision>
	</link>
	<joint
    name="joint_1"
    type="revolute">
		<origin
      xyz="0 0 0.1538"
      rpy="1.5708 0 -0.099427" />
		<parent
      link="model_0" />
		<child
      link="model_1" />
		<axis
      xyz="0 1 0" />
		<limit
      lower="-3.124"
      upper="3.124"
      effort="56"
      velocity="2.1" />
	</joint>
	<link
    name="model_1">
		<inertial>
			<origin
        xyz="0.024756 0.088183 -0.029375"
        rpy="0 0 0" />
			<mass
        value="1.5579" />
			<inertia
        ixx="0.0066699"
        ixy="-0.0011099"
        ixz="0.00050315"
        iyy="0.0037281"
        iyz="0.0018557"
        izz="0.005647" />
		</inertial>
		<visual>
			<origin
        xyz="0 0 0"
        rpy="0 0 0" />
			<geometry>
				<mesh filename="../meshes/model_1.dae" />
			</geometry>
		</visual>
		<collision>
			<origin
        xyz="0 0 0"
        rpy="0 0 0" />
			<geometry>
				<mesh
          filename="../collision_meshes/model_1.STL" />
			</geometry>
		</collision>
	</link>
	<joint
    name="joint_2"
    type="revolute">
		<origin
      xyz="-0.01 0.130199991226196 -0.0559999990463257"
      rpy="0 0 0" />
		<parent
      link="model_1" />
		<child
      link="model_2" />
		<axis
      xyz="1 0 0" />
		<limit
      lower="-2.705"
      upper="1.22"
      effort="56"
      velocity="2.1" />
	</joint>
	<link
    name="model_2">
		<inertial>
			<origin
        xyz="-0.030948 0.096294 0.010957"
        rpy="0 0 0" />
			<mass
        value="2.1446" />
			<inertia
        ixx="0.021432"
        ixy="-0.000118"
        ixz="-0.00015109"
        iyy="0.0033628"
        iyz="-0.00033186"
        izz="0.019582" />
		</inertial>
		<visual>
			<origin
        xyz="0 0 0"
        rpy="0 0 0" />
			<geometry>
				<mesh filename="../meshes/model_2.dae" />
			</geometry>
		</visual>
		<collision>
			<origin
        xyz="0 0 0"
        rpy="0 0 0" />
			<geometry>
				<mesh filename="../collision_meshes/model_2.STL" />
			</geometry>
		</collision>
	</link>
	<joint
    name="joint_3"
    type="revolute">
		<origin
      xyz="-0.000999999999999999 0.205 0"
      rpy="0 0 0" />
		<parent
      link="model_2" />
		<child
      link="model_3" />
		<axis
      xyz="1 0 0" />
		<limit
      lower="-2.79"
      upper="0.785"
      effort="28"
      velocity="2.1" />
	</joint>
	<link
    name="model_3">
		<inertial>
			<origin
        xyz="0.039968 0.020456 0.017312"
        rpy="0 0 0" />
			<mass
        value="1.0325" />
			<inertia
        ixx="0.0027836"
        ixy="0.00031853"
        ixz="0.00020259"
        iyy="0.0019532"
        iyz="-0.00074485"
        izz="0.0022004" />
		</inertial>
		<visual>
			<origin
        xyz="0 0 0"
        rpy="0 0 0" />
			<geometry>
				<mesh
          filename="../meshes/model_3.dae" />
			</geometry>
		</visual>
		<collision>
			<origin
        xyz="0 0 0"
        rpy="0 0 0" />
			<geometry>
				<mesh
          filename="../collision_meshes/model_3.STL" />
			</geometry>
		</collision>
	</link>
	<joint
    name="joint_4"
    type="revolute">
		<origin
      xyz="0.011 0.0925 0.0560000038146973"
      rpy="0 0 0" />
		<parent
      link="model_3" />
		<child
      link="model_4" />
		<axis
      xyz="0 1 0" />
		<limit
      lower="-3.124"
      upper="3.124"
      effort="12"
      velocity="2.1" />
	</joint>
	<link
    name="model_4">
		<inertial>
			<origin
        xyz="0.0088044 0.083627 5.089E-06"
        rpy="0 0 0" />
			<mass
        value="1.2718" />
			<inertia
        ixx="0.0047388"
        ixy="-0.00098815"
        ixz="-4.7828E-08"
        iyy="0.0018841"
        iyz="-1.0193E-07"
        izz="0.0050839" />
		</inertial>
		<visual>
			<origin
        xyz="0 0 0"
        rpy="0 0 0" />
			<geometry>
				<mesh
          filename="../meshes/model_4.dae" />
			</geometry>
		</visual>
		<collision>
			<origin
        xyz="0 0 0"
        rpy="0 0 0" />
			<geometry>
				<mesh
          filename="../collision_meshes/model_4.STL" />
			</geometry>
		</collision>
	</link>
	<joint
    name="joint_5"
    type="revolute">
		<origin
      xyz="0.0284999990463257 0.196900019580026 0"
      rpy="0 0 0" />
		<parent
      link="model_4" />
		<child
      link="model_5" />
		<axis
      xyz="1 0 0" />
		<limit
      lower="-2.705"
      upper="0.1745"
      effort="12"
      velocity="2.1" />
	</joint>
	<link name="model_5">
		<inertial>
			<origin
        xyz="-0.040077 0.0069432 0.034275"
        rpy="0 0 0" />
			<mass
        value="1.1466" />
			<inertia
        ixx="0.0029513"
        ixy="-2.4541E-05"
        ixz="-0.0001236"
        iyy="0.0024685"
        iyz="-0.00026732"
        izz="0.0016456" />
		</inertial>
		<visual>
			<origin
        xyz="0 0 0"
        rpy="0 0 0" />
			<geometry>
				<mesh filename="../meshes/model_5.dae" />
			</geometry>
		</visual>
		<collision>
			<origin
        xyz="0 0 0"
        rpy="0 0 0" />
			<geometry>
				<mesh filename="../collision_meshes/model_5.STL" />
			</geometry>
		</collision>
	</link>
	<joint
    name="joint_6"
    type="revolute">
		<origin
      xyz="-0.0370053384499087 0.0730999755859369 0.0649930070625906"
      rpy="0 0 0" />
		<parent
      link="model_5" />
		<child
      link="model_6" />
		<axis
      xyz="0 1 0" />
		<limit
      lower="-3.124"
      upper="3.124"
      effort="12"
      velocity="2.1" />
	</joint>
	<link
    name="model_6">
		<inertial>
			<origin
        xyz="-0.000142665971082133 0.0595900398887675 1.06525794199841E-05"
        rpy="0 0 0" />
			<mass
        value="0.325474111337899" />
			<inertia
        ixx="0.000175988934427266"
        ixy="2.26130874118183E-08"
        ixz="3.93556718587556E-10"
        iyy="0.000146204107589989"
        iyz="-7.78267014393331E-08"
        izz="0.000193274376845142" />
		</inertial>
		<visual>
			<origin
        xyz="0 0 0"
        rpy="0 0 0" />
			<geometry>
				<mesh filename="../meshes/model_6.dae" />
			</geometry>
		</visual>
		<collision>
			<origin
        xyz="0 0 0"
        rpy="0 0 0" />
			<geometry>
				<mesh filename="../collision_meshes/model_6.STL" />
			</geometry>
		</collision>
	</link>
	<joint
    name="joint_7"
    type="prismatic">
		<origin
      xyz="0.0149999987787376 0.169650003051758 0.000999999640871954"
      rpy="3.14159265358979 0 3.14159265358979" />
		<parent
      link="model_6" />
		<child
      link="gripper_1" />
		<axis
      xyz="-1 0 0" />
		<limit
      lower="-0.002"
      upper="0.005"
      effort="215"
      velocity="0.076" />
	</joint>
	<link
    name="gripper_1">
		<inertial>
			<origin
        xyz="0.0219923201024402 -0.0102338098461754 0.0057136148339931"
        rpy="0 0 0" />
			<mass
        value="0.00590732603009103" />
			<inertia
        ixx="4.76121503547931E-07"
        ixy="-3.01445009083961E-07"
        ixz="1.07509645927906E-07"
        iyy="1.02181933799841E-06"
        iyz="9.37757679495404E-08"
        izz="1.29961324544833E-06" />
		</inertial>
		<visual>
			<origin
        xyz="0 0 0"
        rpy="0 0 0" />
			<geometry>
				<mesh filename="../meshes/gripper_1.dae" />
			</geometry>
		</visual>
		<collision>
			<origin
        xyz="0 0 0"
        rpy="0 0 0" />
			<geometry>
				<mesh
          filename="../collision_meshes/gripper_1.STL" />
			</geometry>
		</collision>
	</link>
	<joint
    name="joint_8"
    type="prismatic">
		<origin
      xyz="-0.0150000012212624 0.169650003051758 -0.00100000035912805"
      rpy="0 0 0" />
		<parent
      link="model_6" />
		<child
      link="gripper_2" />
		<axis
      xyz="-1 0 0" />
		<limit
      lower="-0.002"
      upper="0.005"
      effort="215"
      velocity="0.076" />
	  <mimic joint="joint_7" multiplier="1" offset="0"/>
	</joint>
	<link
    name="gripper_2">
		<inertial>
			<origin
        xyz="0.0219923201024402 -0.0102338098461754 0.0057136148339931"
        rpy="0 0 0" />
			<mass
        value="0.00590732603009103" />
			<inertia
        ixx="4.76121503547932E-07"
        ixy="-3.01445009083961E-07"
        ixz="1.07509645927906E-07"
        iyy="1.02181933799841E-06"
        iyz="9.37757679495403E-08"
        izz="1.29961324544833E-06" />
		</inertial>
		<visual>
			<origin
        xyz="0 0 0"
        rpy="0 0 0" />
			<geometry>
				<mesh
          filename="../meshes/gripper_2.dae" />
			</geometry>
		</visual>
		<collision>
			<origin
        xyz="0 0 0"
        rpy="0 0 0" />
			<geometry>
				<mesh
          filename="../collision_meshes/gripper_2.STL" />
			</geometry>
		</collision>
	</link>
	<!-- ToolPoint for planning -->
	<link name="tool_point">
		<inertial>
			<mass value="0" />
			<origin rpy="0 0 0" xyz="0 0 0" />
			<inertia ixx="0" ixy="0" ixz="0" iyy="0" iyz="0" izz="0" />
		</inertial>
	</link>
	<joint name="toolpoint_fixed_joint" type="fixed">
		<origin rpy="0 0 0" xyz="0 0.17 0" />
		<parent link="model_6" />
		<child link="tool_point" />
	</joint>
</robot>